Workbook
Name air_density: Conversions!$M$11
Name Baseline: Menus!$I$2:$I$3
Name Carbon_01: OFFSET(Carbon!$U$6,0,0,Carbon!$S$3,1)
Name Carbon_02: OFFSET(Carbon!$V$6,0,0,Carbon!$S$3,1)
Name Carbon_03: OFFSET(Carbon!$W$6,0,0,Carbon!$S$3,1)
Name Carbon_04: OFFSET(Carbon!$X$6,0,0,Carbon!$S$3,1)
Name Carbon_05: OFFSET(Carbon!$Y$6,0,0,Carbon!$S$3,1)
Name Carbon_06: OFFSET(Carbon!$Z$6,0,0,Carbon!$S$3,1)
Name Carbon_07: OFFSET(Carbon!$AA$6,0,0,Carbon!$S$3,1)
Name Carbon_08: OFFSET(Carbon!$AB$6,0,0,Carbon!$S$3,1)
Name Carbon_09: OFFSET(Carbon!$AC$6,0,0,Carbon!$S$3,1)
Name Carbon_10: OFFSET(Carbon!$AD$6,0,0,Carbon!$S$3,1)
Name Carbon_11: OFFSET(Carbon!$AE$6,0,0,Carbon!$S$3,1)
Name Carbon_12: OFFSET(Carbon!$AF$6,0,0,Carbon!$S$3,1)
Name Carbon_13: OFFSET(Carbon!$AG$6,0,0,Carbon!$S$3,1)
Name Carbon_14: OFFSET(Carbon!$AH$6,0,0,Carbon!$S$3,1)
Name Carbon_15: OFFSET(Carbon!$AI$6,0,0,Carbon!$S$3,1)
Name Carbon_16: OFFSET(Carbon!$AJ$6,0,0,Carbon!$S$3,1)
Name Carbon_17: OFFSET(Carbon!$AK$6,0,0,Carbon!$S$3,1)
Name Carbon_18: OFFSET(Carbon!$AL$6,0,0,Carbon!$S$3,1)
Name Carbon_19: OFFSET(Carbon!$AM$6,0,0,Carbon!$S$3,1)
Name Carbon_20: OFFSET(Carbon!$AN$6,0,0,Carbon!$S$3,1)
Name Carbon_AdditionalFuel: OFFSET(Carbon!#REF!,0,0,Carbon!$S$3,1 )
Name Carbon_AdditionalFuel: OFFSET(Cost!#REF!,0,0,Cost!$S$3,1 )
Name Carbon_AdditionalFuel: OFFSET(SiteE!#REF!,0,0,SiteE!$S$3,1 )
Name Carbon_AdditionalFuel: OFFSET(SourceE!#REF!,0,0,SourceE!$S$3,1 )
Name Carbon_AdditionalFuel: OFFSET(#REF!,0,0,#REF!,1 )
Name Carbon_DistrictCooling: OFFSET(Carbon!#REF!,0,0,Carbon!$S$3,1 )
Name Carbon_DistrictCooling: OFFSET(Cost!#REF!,0,0,Cost!$S$3,1 )
Name Carbon_DistrictCooling: OFFSET(SiteE!#REF!,0,0,SiteE!$S$3,1 )
Name Carbon_DistrictCooling: OFFSET(SourceE!#REF!,0,0,SourceE!$S$3,1 )
Name Carbon_DistrictCooling: OFFSET(#REF!,0,0,#REF!,1 )
Name Carbon_DistrictHeating: OFFSET(Carbon!#REF!,0,0,Carbon!$S$3,1 )
Name Carbon_DistrictHeating: OFFSET(Cost!#REF!,0,0,Cost!$S$3,1 )
Name Carbon_DistrictHeating: OFFSET(SiteE!#REF!,0,0,SiteE!$S$3,1 )
Name Carbon_DistrictHeating: OFFSET(SourceE!#REF!,0,0,SourceE!$S$3,1 )
Name Carbon_DistrictHeating: OFFSET(#REF!,0,0,#REF!,1 )
Name Carbon_Electricity: OFFSET(Carbon!#REF!,0,0,Carbon!$S$3,1 )
Name Carbon_Electricity: OFFSET(Cost!#REF!,0,0,Cost!$S$3,1 )
Name Carbon_Electricity: OFFSET(SiteE!#REF!,0,0,SiteE!$S$3,1 )
Name Carbon_Electricity: OFFSET(SourceE!#REF!,0,0,SourceE!$S$3,1 )
Name Carbon_Electricity: OFFSET(#REF!,0,0,#REF!,1 )
Name Carbon_NaturalGas: OFFSET(Carbon!#REF!,0,0,Carbon!$S$3,1 )
Name Carbon_NaturalGas: OFFSET(Cost!#REF!,0,0,Cost!$S$3,1 )
Name Carbon_NaturalGas: OFFSET(SiteE!#REF!,0,0,SiteE!$S$3,1 )
Name Carbon_NaturalGas: OFFSET(SourceE!#REF!,0,0,SourceE!$S$3,1 )
Name Carbon_NaturalGas: OFFSET(#REF!,0,0,#REF!,1 )
Name Carbon_Unc: OFFSET(Carbon!#REF!,0,0,Carbon!$S$3,1 )
Name Carbon_Unc: OFFSET(Cost!#REF!,0,0,Cost!$S$3,1 )
Name Carbon_Unc: OFFSET(SiteE!#REF!,0,0,SiteE!$S$3,1 )
Name Carbon_Unc: OFFSET(SourceE!#REF!,0,0,SourceE!$S$3,1 )
Name Carbon_Unc: OFFSET(#REF!,0,0,#REF!,1 )
Name CarbonEI_11: OFFSET(Carbon!$AE$20,0,0,Carbon!$S$3,1)
Name Case_Names: OFFSET(Carbon!$S$6,0,0,Carbon!$S$3,1 )
Name Case_Names: OFFSET(Cost!$S$6,0,0,Cost!$S$3,1 )
Name Case_Names: OFFSET(SiteE!$S$6,0,0,SiteE!$S$3,1 )
Name Case_Names: OFFSET(SourceE!$S$6,0,0,SourceE!$S$3,1 )
Name Case_Names: OFFSET(#REF!,0,0,#REF!,1 )
Name CEI_01: OFFSET(Carbon!$U$20,0,0,Carbon!$S$3,1)
Name CEI_02: OFFSET(Carbon!$V$20,0,0,Carbon!$S$3,1)

Sheet Home
A1: Energy Results Comparison
B3: Instructions | O3: About
B4: This spreadsheet has been designed to allow the easy comparison of various energy scenarios during early and later design phases using both simulated and postprocessed information. It been optimized to automatically use transcribed data from the scripts, but results from other energy modelling programs or external calculations can be manually inputted. The worksheet can generate graphs and tables for reports and report on LEED points for energy and renewable energy. | O4: Energy Results Comparison Worksheet
O6: Version: | Q6: 4.52
B7: 1. Enter design and utility information in tab 'Project Information' | O7: Last Update: | Q7: 45980
B8: 2. Perform energy simulations in energy modelling program | O8: By: | Q8: EJG
B9: 3. If applicable, use the scripting tools available for each platform to format the results for the universal energy results format | O9: Version Notes: | Q9: Changed graph and table pages
B10: 4. If applicable, use the scripting tools to import the Baseline information into the 'BL Data' tab and the Proposed cases into the 'Proposed Data' tab | Q10: Added gross floor area for 2030 reporting table
B11: 5. Use the 'LEED BL', 'Code BL' and 'Proposed Tabs' to pull in cases from the 'BL Data' and 'Proposed Data' tab | Q11: Updated LEED point calculation
B12: 6. Use the input cells in these worksheets to postprocess enduse data or to manually add in results from the energy modeling program | Q12: Made provisions for LEED v5
B13: 7. Use the remaning tabs to generate graphs and tables for reports | Q13: Changed control for including process loads to 'Project Info' page
Q14: Refinement to report tables
Q15: Fixed bugs in Name
B16: Legend | Q16: Fixed bugs in renewable energy calculation
Q17: Updated the energy cost and carbon factors input methodology
B18: SI | C18: Cell with pull down menu | Q18: Added consistency to area for nromalized calculations when conflict between entered value and model
B20: 2464 | C20: Cell to input information in
B22: =B20*2 -> 4928 | C22: Cell that contains a formula and is automatically calculated
C24: Cell does not apply

Sheet Project Info
A1: Project Information
B3: Project Information | G3: Worksheet Units
B4: Project Name | D4: Casa | G4: Select Project Units | I4: IP
B5: ASHRAE Climate Zone | D5: 3B | G5: Select Energy Units for Input | I5: kBtu | K5: Specify the units of energy that will be entered in the tables (as output from the energy modelling program)
B6: Program Type | D6: All Others | G6: Select Energy Units for Output | I6: kBtu | K6: Specify the units of energy to report in the tables and graphs. If different from input units, a conversion will be performed
B7: Gross Conditioned Floor Area | D7: 13652 | E7: =IF($I$4="SI","m²","ft²") -> ft²
G8: Additional End Use Categories | K8: Use this section to define end uses that are not accounted for in the typical end use categories
B9: Baseline Information | I9: Misc 1 | J9: Misc 2
B10: AIA 2030 Benchmark EUI (BmEUI) | D10: 43 | E10: kBtu/ft2 | G10: End Use Name | K10: Add the names of any atypical end uses that will be used in this project for inclusion in the calcualtions
B11: AIA 2030 Target Savings | D11: 0.9 | G11: Fuel | I11: Electricity | J11: Gas | K11: Specify fuel type of end use
B12: LEED Version | D12: LEED v4 | G12: Process Load? | I12: No | J12: Yes | K12: Specify if these end uses are a process load or not
B13: LEED Type | D13: New Construction
B14: LEED Subcategory | D14: School | G14: Site to Source Ratio
B15: Energy Code Standard | D15: Title 24 | I15: =Menus!$A$17 -> Electricity | J15: =Menus!$A$18 -> Gas | K15: =Menus!$A$19 -> Additional Fuel | L15: =Menus!$A$20 -> District Cooling | M15: =Menus!$A$21 -> District Heating
B16: Energy Code Includes Process Loads? | D16: Yes | G16: Site to Source Ratio | I16: 2.8 | J16: 1.05 | L16: 0.91 | M16: 1.2 | N16: Energy Star US and Canadian Source to Site Ratios
B18: Performance Goals | G18: Carbon Emissions Factors
D19: LEED | E19: Code | G19: Select Carbon Emissions Method | I19: Enter Flat Rate | K19: Specify if the carbon emissions will be calculated in the flat rates supplied below, or the calculated virtual rate from imported energy model data
B20: Energy Savings Goal | D20: NA | E20: NA
B21: Carbon Savings Goal | D21: NA | E21: NA | I21: =Menus!$A$17 -> Electricity | J21: =Menus!$A$18 -> Gas | K21: =Menus!$A$19 -> Additional Fuel | L21: =Menus!$A$20 -> District Cooling | M21: =Menus!$A$21 -> District Heating
B22: Energy Cost Savings Goal | D22: NA | E22: NA | G22: =IF($I$4=Menus!$A$2,Menus!$G$6,Menus!$G$7) -> kg CO2e | I22: 0.404 | J22: =IF($I$4="SI",0.18053,0.05306) -> 0.05306 | L22: 1 | M22: 1 | N22: Energy Star US and Canadian Emissions Factors
G23: Carbon Units | I23: kWh | J23: =IF($I$4="SI","kWh","kBtu") -> kBtu | K23: kWh | L23: kWh | M23: kWh
B25: QA/QC | G25: Energy Cost Factors
B26: Author | D26: Urvi Pawar | G26: Select Energy Cost Method | I26: Enter Flat Rate | K26: Specify if the energy cost will be calculated in the flat rates supplied below, or the calculated virtual rate from imported energy model data
B27: Date | D27: 2026-06-17
B28: Uncertainty Factor | D28: 0 | I28: =Menus!$A$17 -> Electricity | J28: =Menus!$A$18 -> Gas | K28: =Menus!$A$19 -> Additional Fuel | L28: =Menus!$A$20 -> District Cooling | M28: =Menus!$A$21 -> District Heating
G29: Unit Cost | I29: 0.124 | J29: 1.45
G30: Cost Unit | I30: kWh | J30: Therm | K30: 1000 ft3 Gas | L30: kWh | M30: kWh
G39: Converted Factors
I40: =I15 -> Electricity | J40: =J15 -> Gas | K40: =K15 -> Additional Fuel | L40: District Cooling | M40: District Heating
G41: Carbon Flat Rate Converted | I41: =IFERROR(I$22/INDEX(Conversions!$C$6:$I$12,MATCH($I$6,Conversions!$B$6:$B$12,0),MATCH(I$23,Conversions!$C$5:$I$5,0)),0) -> 0.11840077 | J41: =IFERROR(J$22/INDEX(Conversions!$C$6:$I$12,MATCH($I$6,Conversions!$B$6:$B$12,0),MATCH(J$23,Conversions!$C$5:$I$5,0)),0) -> 0.05306 | K41: =IFERROR(K$22/INDEX(Conversions!$C$6:$I$12,MATCH($I$6,Conversions!$B$6:$B$12,0),MATCH(K$23,Conversions!$C$5:$I$5,0)),0) -> 0 | L41: =IFERROR(L$22/INDEX(Conversions!$C$6:$I$12,MATCH($I$6,Conversions!$B$6:$B$12,0),MATCH(L$23,Conversions!$C$5:$I$5,0)),0) -> 0.29307121 | M41: =IFERROR(M$22/INDEX(Conversions!$C$6:$I$12,MATCH($I$6,Conversions!$B$6:$B$12,0),MATCH(M$23,Conversions!$C$5:$I$5,0)),0) -> 0.29307121
G42: Flat Rate Unit Price Converted | I42: =IFERROR(I$29/INDEX(Conversions!$C$6:$I$12,MATCH($I$6,Conversions!$B$6:$B$12,0),MATCH(I$30,Conversions!$C$5:$I$5,0)),0) -> 0.03634083 | J42: =IFERROR(J$29/INDEX(Conversions!$C$6:$I$12,MATCH($I$6,Conversions!$B$6:$B$12,0),MATCH(J$30,Conversions!$C$5:$I$5,0)),0) -> 0.0145 | K42: =IFERROR(K$29/INDEX(Conversions!$C$6:$I$12,MATCH($I$6,Conversions!$B$6:$B$12,0),MATCH(K$30,Conversions!$C$5:$I$5,0)),0) -> 0 | L42: =IFERROR(L$29/INDEX(Conversions!$C$6:$I$12,MATCH($I$6,Conversions!$B$6:$B$12,0),MATCH(L$30,Conversions!$C$5:$I$5,0)),0) -> 0 | M42: =IFERROR(M$29/INDEX(Conversions!$C$6:$I$12,MATCH($I$6,Conversions!$B$6:$B$12,0),MATCH(M$30,Conversions!$C$5:$I$5,0)),0) -> 0
G44: =Calculations!A$9 -> LEED Baseline | I44: ='BL Data'!BB$2 -> 0.11840563 | J44: ='BL Data'!BC$2 -> 0.053 | K44: ='BL Data'!BD$2 -> 0 | L44: ='BL Data'!BE$2 -> 0 | M44: ='BL Data'!BF$2 -> 0
G45: =Calculations!A$10 -> Code Baseline | I45: ='BL Data'!BB$6 -> 0 | J45: ='BL Data'!BC$6 -> 0 | K45: ='BL Data'!BD$6 -> 0 | L45: ='BL Data'!BE$6 -> 0 | M45: ='BL Data'!BF$6 -> 0
G46: =Proposed!C$10 -> Primary 0° | I46: =IFERROR(INDEX('Proposed Data'!BB$2:BB$100, MATCH('Project Info'!$G46,'Proposed Data'!$A$2:$A$100,0))/Calculations!$E$8,0) -> 0.11840563 | J46: =IFERROR(INDEX('Proposed Data'!BC$2:BC$100, MATCH('Project Info'!$G46,'Proposed Data'!$A$2:$A$100,0))/Calculations!$E$8,0) -> 0.053 | K46: =IFERROR(INDEX('Proposed Data'!BD$2:BD$100, MATCH('Project Info'!$G46,'Proposed Data'!$A$2:$A$100,0))/Calculations!$E$8,0) -> 0 | L46: =IFERROR(INDEX('Proposed Data'!BE$2:BE$100, MATCH('Project Info'!$G46,'Proposed Data'!$A$2:$A$100,0))/Calculations!$E$8,0) -> 0 | M46: =IFERROR(INDEX('Proposed Data'!BF$2:BF$100, MATCH('Project Info'!$G46,'Proposed Data'!$A$2:$A$100,0))/Calculations!$E$8,0) -> 0
G47: =Proposed!C$24 -> 0 | I47: =IFERROR(INDEX('Proposed Data'!BB$2:BB$100, MATCH('Project Info'!$G47,'Proposed Data'!$A$2:$A$100,0))/Calculations!$E$8,0) -> 0 | J47: =IFERROR(INDEX('Proposed Data'!BC$2:BC$100, MATCH('Project Info'!$G47,'Proposed Data'!$A$2:$A$100,0))/Calculations!$E$8,0) -> 0 | K47: =IFERROR(INDEX('Proposed Data'!BD$2:BD$100, MATCH('Project Info'!$G47,'Proposed Data'!$A$2:$A$100,0))/Calculations!$E$8,0) -> 0 | L47: =IFERROR(INDEX('Proposed Data'!BE$2:BE$100, MATCH('Project Info'!$G47,'Proposed Data'!$A$2:$A$100,0))/Calculations!$E$8,0) -> 0 | M47: =IFERROR(INDEX('Proposed Data'!BF$2:BF$100, MATCH('Project Info'!$G47,'Proposed Data'!$A$2:$A$100,0))/Calculations!$E$8,0) -> 0
G48: =Proposed!C$38 -> 0 | I48: =IFERROR(INDEX('Proposed Data'!BB$2:BB$100, MATCH('Project Info'!$G48,'Proposed Data'!$A$2:$A$100,0))/Calculations!$E$8,0) -> 0 | J48: =IFERROR(INDEX('Proposed Data'!BC$2:BC$100, MATCH('Project Info'!$G48,'Proposed Data'!$A$2:$A$100,0))/Calculations!$E$8,0) -> 0 | K48: =IFERROR(INDEX('Proposed Data'!BD$2:BD$100, MATCH('Project Info'!$G48,'Proposed Data'!$A$2:$A$100,0))/Calculations!$E$8,0) -> 0 | L48: =IFERROR(INDEX('Proposed Data'!BE$2:BE$100, MATCH('Project Info'!$G48,'Proposed Data'!$A$2:$A$100,0))/Calculations!$E$8,0) -> 0 | M48: =IFERROR(INDEX('Proposed Data'!BF$2:BF$100, MATCH('Project Info'!$G48,'Proposed Data'!$A$2:$A$100,0))/Calculations!$E$8,0) -> 0
G49: =Proposed!C$52 -> 0 | I49: =IFERROR(INDEX('Proposed Data'!BB$2:BB$100, MATCH('Project Info'!$G49,'Proposed Data'!$A$2:$A$100,0))/Calculations!$E$8,0) -> 0 | J49: =IFERROR(INDEX('Proposed Data'!BC$2:BC$100, MATCH('Project Info'!$G49,'Proposed Data'!$A$2:$A$100,0))/Calculations!$E$8,0) -> 0 | K49: =IFERROR(INDEX('Proposed Data'!BD$2:BD$100, MATCH('Project Info'!$G49,'Proposed Data'!$A$2:$A$100,0))/Calculations!$E$8,0) -> 0 | L49: =IFERROR(INDEX('Proposed Data'!BE$2:BE$100, MATCH('Project Info'!$G49,'Proposed Data'!$A$2:$A$100,0))/Calculations!$E$8,0) -> 0 | M49: =IFERROR(INDEX('Proposed Data'!BF$2:BF$100, MATCH('Project Info'!$G49,'Proposed Data'!$A$2:$A$100,0))/Calculations!$E$8,0) -> 0
G50: =Proposed!C$66 -> 0 | I50: =IFERROR(INDEX('Proposed Data'!BB$2:BB$100, MATCH('Project Info'!$G50,'Proposed Data'!$A$2:$A$100,0))/Calculations!$E$8,0) -> 0 | J50: =IFERROR(INDEX('Proposed Data'!BC$2:BC$100, MATCH('Project Info'!$G50,'Proposed Data'!$A$2:$A$100,0))/Calculations!$E$8,0) -> 0 | K50: =IFERROR(INDEX('Proposed Data'!BD$2:BD$100, MATCH('Project Info'!$G50,'Proposed Data'!$A$2:$A$100,0))/Calculations!$E$8,0) -> 0 | L50: =IFERROR(INDEX('Proposed Data'!BE$2:BE$100, MATCH('Project Info'!$G50,'Proposed Data'!$A$2:$A$100,0))/Calculations!$E$8,0) -> 0 | M50: =IFERROR(INDEX('Proposed Data'!BF$2:BF$100, MATCH('Project Info'!$G50,'Proposed Data'!$A$2:$A$100,0))/Calculations!$E$8,0) -> 0
G51: =Proposed!C$80 -> 0 | I51: =IFERROR(INDEX('Proposed Data'!BB$2:BB$100, MATCH('Project Info'!$G51,'Proposed Data'!$A$2:$A$100,0))/Calculations!$E$8,0) -> 0 | J51: =IFERROR(INDEX('Proposed Data'!BC$2:BC$100, MATCH('Project Info'!$G51,'Proposed Data'!$A$2:$A$100,0))/Calculations!$E$8,0) -> 0 | K51: =IFERROR(INDEX('Proposed Data'!BD$2:BD$100, MATCH('Project Info'!$G51,'Proposed Data'!$A$2:$A$100,0))/Calculations!$E$8,0) -> 0 | L51: =IFERROR(INDEX('Proposed Data'!BE$2:BE$100, MATCH('Project Info'!$G51,'Proposed Data'!$A$2:$A$100,0))/Calculations!$E$8,0) -> 0 | M51: =IFERROR(INDEX('Proposed Data'!BF$2:BF$100, MATCH('Project Info'!$G51,'Proposed Data'!$A$2:$A$100,0))/Calculations!$E$8,0) -> 0
G52: =Proposed!C$94 -> 0 | I52: =IFERROR(INDEX('Proposed Data'!BB$2:BB$100, MATCH('Project Info'!$G52,'Proposed Data'!$A$2:$A$100,0))/Calculations!$E$8,0) -> 0 | J52: =IFERROR(INDEX('Proposed Data'!BC$2:BC$100, MATCH('Project Info'!$G52,'Proposed Data'!$A$2:$A$100,0))/Calculations!$E$8,0) -> 0 | K52: =IFERROR(INDEX('Proposed Data'!BD$2:BD$100, MATCH('Project Info'!$G52,'Proposed Data'!$A$2:$A$100,0))/Calculations!$E$8,0) -> 0 | L52: =IFERROR(INDEX('Proposed Data'!BE$2:BE$100, MATCH('Project Info'!$G52,'Proposed Data'!$A$2:$A$100,0))/Calculations!$E$8,0) -> 0 | M52: =IFERROR(INDEX('Proposed Data'!BF$2:BF$100, MATCH('Project Info'!$G52,'Proposed Data'!$A$2:$A$100,0))/Calculations!$E$8,0) -> 0
...

Sheet BL Data
A1: Option | B1: Results Path | C1: Timestamp | D1: Climate File | E1: Climate Zone | F1: Heating Unmet Hours | G1: Cooling Unmet Hours | H1: =_xlfn.CONCAT("Total Energy Use ",IF('Project Info'!$I$4=Menus!$A$2,"(kWh)","(kBtu)")) -> Total Energy Use (kBtu) | I1: =_xlfn.CONCAT("Energy Use Intensity ",IF('Project Info'!$I$4=Menus!$A$2,"(kWh/m²)","(kBtu/ft²)")) -> Energy Use Intensity (kBtu/ft²) | J1: =_xlfn.CONCAT("Electricity ",IF('Project Info'!$I$4=Menus!$A$2,"(kWh)","(kBtu)")) -> Electricity (kBtu) | K1: =_xlfn.CONCAT("Gas ",IF('Project Info'!$I$4=Menus!$A$2,"(kWh)","(kBtu)")) -> Gas (kBtu) | L1: =_xlfn.CONCAT("Additional Fuel ",IF('Project Info'!$I$4=Menus!$A$2,"(kWh)","(kBtu)")) -> Additional Fuel (kBtu) | M1: =_xlfn.CONCAT("District Cooling ",IF('Project Info'!$I$4=Menus!$A$2,"(kWh)","(kBtu)")) -> District Cooling (kBtu) | N1: =_xlfn.CONCAT("District Heating ",IF('Project Info'!$I$4=Menus!$A$2,"(kWh)","(kBtu)")) -> District Heating (kBtu) | O1: =_xlfn.CONCAT("Heating - Electricity Energy Use ",IF('Project Info'!$I$4=Menus!$A$2,"(kWh)","(kBtu)")) -> Heating - Electricity Energy Use (kBtu) | P1: =_xlfn.CONCAT("Heating - Gas Energy Use ",IF('Project Info'!$I$4=Menus!$A$2,"(kWh)","(kBtu)")) -> Heating - Gas Energy Use (kBtu) | Q1: =_xlfn.CONCAT("Heating - Additonal Fuel Energy Use ",IF('Project Info'!$I$4=Menus!$A$2,"(kWh)","(kBtu)")) -> Heating - Additonal Fuel Energy Use (kBtu) | R1: =_xlfn.CONCAT("Heating - District Heating Energy Use ",IF('Project Info'!$I$4=Menus!$A$2,"(kWh)","(kBtu)")) -> Heating - District Heating Energy Use (kBtu) | S1: =_xlfn.CONCAT("Cooling - Electricity Energy Use ",IF('Project Info'!$I$4=Menus!$A$2,"(kWh)","(kBtu)")) -> Cooling - Electricity Energy Use (kBtu) | T1: =_xlfn.CONCAT("Cooling - District Energy Use ",IF('Project Info'!$I$4=Menus!$A$2,"(kWh)","(kBtu)")) -> Cooling - District Energy Use (kBtu) | U1: =_xlfn.CONCAT("Interior Lighting - Electricity Energy Use ",IF('Project Info'!$I$4=Menus!$A$2,"(kWh)","(kBtu)")) -> Interior Lighting - Electricity Energy Use (kBtu) | V1: =_xlfn.CONCAT("Exterior Lighting - Electricity Energy Use ",IF('Project Info'!$I$4=Menus!$A$2,"(kWh)","(kBtu)")) -> Exterior Lighting - Electricity Energy Use (kBtu) | W1: =_xlfn.CONCAT("Interior Equipment - Electricity Energy Use ",IF('Project Info'!$I$4=Menus!$A$2,"(kWh)","(kBtu)")) -> Interior Equipment - Electricity Energy Use (kBtu) | X1: =_xlfn.CONCAT("Interior Equipment - Gas Energy Use ",IF('Project Info'!$I$4=Menus!$A$2,"(kWh)","(kBtu)")) -> Interior Equipment - Gas Energy Use (kBtu) | Y1: =_xlfn.CONCAT("Interior Equipment - Additional Fuel Energy Use ",IF('Project Info'!$I$4=Menus!$A$2,"(kWh)","(kBtu)")) -> Interior Equipment - Additional Fuel Energy Use (kBtu) | Z1: =_xlfn.CONCAT("Exterior Equipment - Energy Use ",IF('Project Info'!$I$4=Menus!$A$2,"(kWh)","(kBtu)")) -> Exterior Equipment - Energy Use (kBtu) | AA1: =_xlfn.CONCAT("Fans - Electricity Energy Use ",IF('Project Info'!$I$4=Menus!$A$2,"(kWh)","(kBtu)")) -> Fans - Electricity Energy Use (kBtu) | AB1: =_xlfn.CONCAT("Pumps - Electricity Energy Use ",IF('Project Info'!$I$4=Menus!$A$2,"(kWh)","(kBtu)")) -> Pumps - Electricity Energy Use (kBtu) | AC1: =_xlfn.CONCAT("Heat Rejection - Electricity Energy Use ",IF('Project Info'!$I$4=Menus!$A$2,"(kWh)","(kBtu)")) -> Heat Rejection - Electricity Energy Use (kBtu) | AD1: =_xlfn.CONCAT("Humidification - Electricity Energy Use ",IF('Project Info'!$I$4=Menus!$A$2,"(kWh)","(kBtu)")) -> Humidification - Electricity Energy Use (kBtu) | AE1: =_xlfn.CONCAT("Heat Recovery - Electricity Energy Use ",IF('Project Info'!$I$4=Menus!$A$2,"(kWh)","(kBtu)")) -> Heat Recovery - Electricity Energy Use (kBtu) | AF1: =_xlfn.CONCAT("Water Systems - Electricity Energy Use ",IF('Project Info'!$I$4=Menus!$A$2,"(kWh)","(kBtu)")) -> Water Systems - Electricity Energy Use (kBtu) | AG1: =_xlfn.CONCAT("Water Systems - Gas Energy Use ",IF('Project Info'!$I$4=Menus!$A$2,"(kWh)","(kBtu)")) -> Water Systems - Gas Energy Use (kBtu) | AH1: =_xlfn.CONCAT("Water Systems - Additional Fuel Energy Use ",IF('Project Info'!$I$4=Menus!$A$2,"(kWh)","(kBtu)")) -> Water Systems - Additional Fuel Energy Use (kBtu) | AI1: =_xlfn.CONCAT("Water Systems - District Heating Energy Use ",IF('Project Info'!$I$4=Menus!$A$2,"(kWh)","(kBtu)")) -> Water Systems - District Heating Energy Use (kBtu) | AJ1: =_xlfn.CONCAT("Refrigeration - Electricity Energy Use ",IF('Project Info'!$I$4=Menus!$A$2,"(kWh)","(kBtu)")) -> Refrigeration - Electricity Energy Use (kBtu) | AK1: =_xlfn.CONCAT("Generators Electricity Energy Use ",IF('Project Info'!$I$4=Menus!$A$2,"(kWh)","(kBtu)")) -> Generators Electricity Energy Use (kBtu) | AL1: =_xlfn.CONCAT("Misc 1 - Electricity Energy Use ",IF('Project Info'!$I$4=Menus!$A$2,"(kWh)","(kBtu)")) -> Misc 1 - Electricity Energy Use (kBtu) | AM1: =_xlfn.CONCAT("Misc 2 - Electricity Energy Use ",IF('Project Info'!$I$4=Menus!$A$2,"(kWh)","(kBtu)")) -> Misc 2 - Electricity Energy Use (kBtu) | AN1: =_xlfn.CONCAT("Total Water Use ",IF('Project Info'!$I$4=Menus!$A$2,"(m3)","(kGal)")) -> Total Water Use (kGal) | AO1: =_xlfn.CONCAT("Water Use Intensity ",IF('Project Info'!$I$4=Menus!$A$2,"(m³/m²)","(kGal/ft²)")) -> Water Use Intensity (kGal/ft²) | AP1: =_xlfn.CONCAT("Heat Rejection - Water Use ",IF('Project Info'!$I$4=Menus!$A$2,"(m3)","(kGal)")) -> Heat Rejection - Water Use (kGal) | AQ1: =_xlfn.CONCAT("Humidificatopn - Water Use ",IF('Project Info'!$I$4=Menus!$A$2,"(m3)","(kGal)")) -> Humidificatopn - Water Use (kGal) | AR1: =_xlfn.CONCAT("Water System - Water Use ",IF('Project Info'!$I$4=Menus!$A$2,"(m3)","(kGal)")) -> Water System - Water Use (kGal) | AS1: Total Energy Cost ($) | AT1: =_xlfn.CONCAT("Energy Cost Intensity (",IF('Project Info'!$I$4=Menus!$A$2,Menus!$E$10,Menus!$E$11),")") -> Energy Cost Intensity ($/ft²) | AU1: =_xlfn.CONCAT("Electricity Virtual Rate (",IF('Project Info'!$I$4=Menus!$A$2,Menus!$E$14,Menus!$E$15),")") -> Electricity Virtual Rate ($/kBtu) | AV1: =_xlfn.CONCAT("Gas Virtual Rate (",IF('Project Info'!$I$4=Menus!$A$2,Menus!$E$14,Menus!$E$15),")") -> Gas Virtual Rate ($/kBtu) | AW1: =_xlfn.CONCAT("Additional Fuel Virtual Rate (",IF('Project Info'!$I$4=Menus!$A$2,Menus!$E$14,Menus!$E$15),")") -> Additional Fuel Virtual Rate ($/kBtu) | AX1: =_xlfn.CONCAT("District Cooling Virtual Rate (",IF('Project Info'!$I$4=Menus!$A$2,Menus!$E$14,Menus!$E$15),")") -> District Cooling Virtual Rate ($/kBtu) | AY1: =_xlfn.CONCAT("District Heating Virtual Rate (",IF('Project Info'!$I$4=Menus!$A$2,Menus!$E$14,Menus!$E$15),")") -> District Heating Virtual Rate ($/kBtu) | AZ1: =_xlfn.CONCAT("Total Carbon Emissions (",IF('Project Info'!$I$4=Menus!$A$2,Menus!$G$6,Menus!$G$7),")") -> Total Carbon Emissions (kg CO2e) | BA1: =_xlfn.CONCAT("Carbon Emission Intensity (",IF('Project Info'!$I$4=Menus!$A$2,Menus!$G$10,Menus!$G$11),")") -> Carbon Emission Intensity (kg CO2e/ft²) | BB1: =_xlfn.CONCAT("Electricity Virtual Rate (",IF('Project Info'!$I$4=Menus!$A$2,Menus!$G$14,Menus!$G$15),")") -> Electricity Virtual Rate (kg CO2e/kBtu) | BC1: =_xlfn.CONCAT("Gas Virtual Rate (",IF('Project Info'!$I$4=Menus!$A$2,Menus!$G$14,Menus!$G$15),")") -> Gas Virtual Rate (kg CO2e/kBtu) | BD1: =_xlfn.CONCAT("Additional Fuel Virtual Rate (",IF('Project Info'!$I$4=Menus!$A$2,Menus!$G$14,Menus!$G$15),")") -> Additional Fuel Virtual Rate (kg CO2e/kBtu) | BE1: =_xlfn.CONCAT("District Cooling Virtual Rate (",IF('Project Info'!$I$4=Menus!$A$2,Menus!$G$14,Menus!$G$15),")") -> District Cooling Virtual Rate (kg CO2e/kBtu) | BF1: =_xlfn.CONCAT("District Heating Virtual Rate (",IF('Project Info'!$I$4=Menus!$A$2,Menus!$G$14,Menus!$G$15),")") -> District Heating Virtual Rate (kg CO2e/kBtu) | BG1: =_xlfn.CONCAT("Peak Heating ",IF('Project Info'!$I$4=Menus!$A$2,"(kW)","(kBtuh)")) -> Peak Heating (kBtuh) | BH1: =_xlfn.CONCAT("Peak Heating ",IF('Project Info'!$I$4=Menus!$A$2,"(W/m²)","(Btuh/ft²)")) -> Peak Heating (Btuh/ft²) | BI1: Peak Heating Hour | BJ1: =_xlfn.CONCAT("Peak Cooling ",IF('Project Info'!$I$4=Menus!$A$2,"(kW)","(kBtuh)")) -> Peak Cooling (kBtuh) | BK1: =_xlfn.CONCAT("Peak Cooling ",IF('Project Info'!$I$4=Menus!$A$2,"(W/m²)","(Btuh/ft²)")) -> Peak Cooling (Btuh/ft²) | BL1: Peak Cooling Hour | BM1: Peak Electrical Load (W) | BN1: =_xlfn.CONCAT("Peak Electrical Load Intensity ",IF('Project Info'!$I$4=Menus!$A$2,"(W/m²)","(W/ft²)")) -> Peak Electrical Load Intensity (W/ft²) | BO1: Peak Electricity Hour | BP1: =_xlfn.CONCAT("Conditioned Floor Area ",IF('Project Info'!$I$4=Menus!$A$2,"(m²)","(ft²)")) -> Conditioned Floor Area (ft²) | BQ1: =_xlfn.CONCAT("Total Floor Area ",IF('Project Info'!$I$4=Menus!$A$2,"(m²)","(ft²)")) -> Total Floor Area (ft²) | BR1: =_xlfn.CONCAT("Gross Wall Area ",IF('Project Info'!$I$4=Menus!$A$2,"(m²)","(ft²)")) -> Gross Wall Area (ft²) | BS1: =_xlfn.CONCAT("Above Ground Gross Wall Area ",IF('Project Info'!$I$4=Menus!$A$2,"(m²)","(ft²)")) -> Above Ground Gross Wall Area (ft²) | BT1: =_xlfn.CONCAT("Above Ground North Wall Area ",IF('Project Info'!$I$4=Menus!$A$2,"(m²)","(ft²)")) -> Above Ground North Wall Area (ft²) | BU1: =_xlfn.CONCAT("Above Ground East Wall Area ",IF('Project Info'!$I$4=Menus!$A$2,"(m²)","(ft²)")) -> Above Ground East Wall Area (ft²) | BV1: =_xlfn.CONCAT("Above Ground South Wall Area ",IF('Project Info'!$I$4=Menus!$A$2,"(m²)","(ft²)")) -> Above Ground South Wall Area (ft²) | BW1: =_xlfn.CONCAT("Above Ground East Wall Area ",IF('Project Info'!$I$4=Menus!$A$2,"(m²)","(ft²)")) -> Above Ground East Wall Area (ft²) | BX1: North WWR Nominal (%) | BY1: East WWR Nominal (%) | BZ1: South WWR Nominal (%) | CA1: West WWR Nominal (%) | CB1: Building WWR Actual (%) | CC1: North WWR Actual (%) | CD1: East WWR Actual (%) | CE1: South WWR Actual (%) | CF1: West WWR Actual (%) | CG1: =_xlfn.CONCAT("Gross Roof Area ",IF('Project Info'!$I$4=Menus!$A$2,"(m²)","(ft²)")) -> Gross Roof Area (ft²) | CH1: Skylight Roof Ratio (%) | CI1: Exterior Wall to Floor Area Ratio | CJ1: Exterior Roof to Floor Area Ratio | CK1: Exterior Envelope to Floor Area Ratio | CL1: North Shading Type | CM1: North Shading Ratio (%) | CN1: West Shading Type | CO1: West Shading Ratio (%) | CP1: South Shading Type | CQ1: South Shading Ratio (%) | CR1: East Shading Type | CS1: East Shading Ratio (%) | CT1: =_xlfn.CONCAT("Vertical Weighted U-Value ",IF('Project Info'!$D$7=Menus!$C$2,"(W/m²·K)","(Btu/h·ft²·F)")) -> Vertical Weighted U-Value (Btu/h·ft²·F) | CU1: =_xlfn.CONCAT("Vertical Weighted R-Value ",IF('Project Info'!$D$7=Menus!$C$2,"(m²·K/W)","(ft²·h·F/Btu )")) -> Vertical Weighted R-Value (ft²·h·F/Btu ) | CV1: =_xlfn.CONCAT("Wall U-Value ",IF('Project Info'!$D$7=Menus!$C$2,"(W/m²·K)","(Btu/h·ft²·F)")) -> Wall U-Value (Btu/h·ft²·F) | CW1: =_xlfn.CONCAT("Wall 2 U-Value ",IF('Project Info'!$D$7=Menus!$C$2,"(W/m²·K)","(Btu/h·ft²·F)")) -> Wall 2 U-Value (Btu/h·ft²·F) | CX1: =_xlfn.CONCAT("Roof U-Value ",IF('Project Info'!$D$7=Menus!$C$2,"(W/m²·K)","(Btu/h·ft²·F)")) -> Roof U-Value (Btu/h·ft²·F) | CY1: =_xlfn.CONCAT("Exposed Floor U-Value ",IF('Project Info'!$D$7=Menus!$C$2,"(W/m²·K)","(Btu/h·ft²·F)")) -> Exposed Floor U-Value (Btu/h·ft²·F) | CZ1: =_xlfn.CONCAT("Slab on Grade U-Value ",IF('Project Info'!$D$7=Menus!$C$2,"(W/m²·K)","(Btu/h·ft²·F)")) -> Slab on Grade U-Value (Btu/h·ft²·F) | DA1: =_xlfn.CONCAT("Assembly U-Value ",IF('Project Info'!$D$7=Menus!$C$2,"(W/m²·K)","(Btu/h·ft²·F)")) -> Assembly U-Value (Btu/h·ft²·F) | DB1: =_xlfn.CONCAT("Glass U-Value ",IF('Project Info'!$D$7=Menus!$C$2,"(W/m²·K)","(Btu/h·ft²·F)")) -> Glass U-Value (Btu/h·ft²·F) | DC1: Glass SHGC | DD1: Glass VLT | DE1: Glass LSG | DF1: =_xlfn.CONCAT("Infiltration Rate ",IF('Project Info'!$D$7=Menus!$C$2,"(m³/s/m² façade)","(CFM/ft² facade)")) -> Infiltration Rate (CFM/ft² facade) | DG1: =_xlfn.CONCAT("Lighting Power Density ",IF('Project Info'!$D$7=Menus!$C$2,"(W/m²)","(W/ft²)")) -> Lighting Power Density (W/ft²) | DH1: =_xlfn.CONCAT("Conditioned Lighting Power Density ",IF('Project Info'!$D$7=Menus!$C$2,"(W/m²)","(W/ft²)")) -> Conditioned Lighting Power Density (W/ft²) | DI1: =_xlfn.CONCAT("Occupant Density ",IF('Project Info'!$D$7=Menus!$C$2,"(m/person²)","(ft²/person)")) -> Occupant Density (ft²/person) | DJ1: =_xlfn.CONCAT("Conditioned Occupant Density ",IF('Project Info'!$D$7=Menus!$C$2,"(m/person²)","(ft²/person)")) -> Conditioned Occupant Density (ft²/person) | DK1: =_xlfn.CONCAT("Equipment Power Density ",IF('Project Info'!$D$7=Menus!$C$2,"(W/m²)","(W/ft²)")) -> Equipment Power Density (W/ft²) | DL1: =_xlfn.CONCAT("Conditioned Equipment Power Density ",IF('Project Info'!$D$7=Menus!$C$2,"(W/m²)","(W/ft²)")) -> Conditioned Equipment Power Density (W/ft²) | DM1: =_xlfn.CONCAT("Total Ventilation Air Flow Rate ",IF('Project Info'!$D$7=Menus!$C$2,"(m²/s)","(CFM)")) -> Total Ventilation Air Flow Rate (CFM) | DN1: =_xlfn.CONCAT("Ventilation Air Flow Rate per Area ",IF('Project Info'!$D$7=Menus!$C$2,"(m3/s/m²)","(CFM/ft²)")) -> Ventilation Air Flow Rate per Area (CFM/ft²) | DO1: =_xlfn.CONCAT("Total Heating Airflow Rate ",IF('Project Info'!$D$7=Menus!$C$2,"(m²/s)","(CFM)")) -> Total Heating Airflow Rate (CFM) | DP1: =_xlfn.CONCAT("Heating Airflow Rate per Area ",IF('Project Info'!$D$7=Menus!$C$2,"(m3/s/m²)","(CFM/ft²)")) -> Heating Airflow Rate per Area (CFM/ft²) | DQ1: =_xlfn.CONCAT("Total Cooling Airflow Rate ",IF('Project Info'!$D$7=Menus!$C$2,"(m²/s)","(CFM)")) -> Total Cooling Airflow Rate (CFM) | DR1: =_xlfn.CONCAT("Cooling Airflow Rate per Area ",IF('Project Info'!$D$7=Menus!$C$2,"(m3/s/m²)","(CFM/ft²)")) -> Cooling Airflow Rate per Area (CFM/ft²) | DS1: Chiller Efficiency (COP) | DT1: Boiler Efficiency (COP) | DU1: DX Cooling Efficiency (COP) | DV1: DX Heating Efficiency (HSPF) | DW1: Heat Pump Cooling Efficiency (COP) | DX1: Heat Pump Heating Efficiency (COP) | DY1: Total Fan Power (kW) | DZ1: Total Pump Power (kW) | EA1: Service Hot Water Thermal Efficiency (COP) | EB1: Exterior Lighting (kW)
A2: ASHRAE 90.1-2010 Baseline 0° | B2: Casa De Amparo_v4z 1.pdf | C2: Jun 11, 2026 - 10:50 PM | D2: ASHRAE 90.1-2010 BASELINE ** Climate Zone 10 CA USA CTZRV2 WMO#=722860 | E2: 3B | F2: 50 | G2: 1565 | H2: 693000 | I2: 50.76 | J2: 693171.68 | K2: 0 | L2: 0 | M2: 0 | N2: 0 | O2: 37501.292 | P2: 0 | Q2: 0 | R2: 0 | S2: 145091.89 | T2: 0 | U2: 153372.81 | V2: 0 | W2: 180081.95 | X2: 0 | Y2: 0 | Z2: 0 | AA2: 177123.74 | AB2: 0 | AC2: 0 | AD2: 0 | AE2: 0 | AF2: 0 | AG2: 0 | AH2: 0 | AI2: 0 | AJ2: 0 | AK2: 0 | AL2: 0 | AM2: 0 | AN2: 0 | AO2: 0 | AP2: 0 | AQ2: 0 | AR2: 0 | AS2: 25385.3 | AT2: 1.8594565 | AU2: 0.036342321 | AV2: 0 | AW2: 0 | AX2: 0 | AY2: 0 | AZ2: 82075.428 | BA2: 6.011971 | BB2: 0.11840563 | BC2: 0.053 | BD2: 0 | BE2: 0 | BF2: 0 | BG2: 786 | BH2: 57.6 | BJ2: 360 | BK2: 26.4 | BM2: 49000 | BN2: 3.6 | BP2: 13652 | BQ2: 21103 | BR2: 11729 | BS2: 11729 | BT2: 2721 | BU2: 2651 | BV2: 3382 | BW2: 2975 | BX2: 8.2 | BY2: 10.4 | BZ2: 5.1 | CA2: 5.2 | CB2: 7.05 | CC2: 8.2322675 | CD2: 10.448887 | CE2: 5.0561798 | CF2: 5.210084 | CG2: 15695 | CH2: 0 | CI2: 0.85914152 | CJ2: 1.1496484 | CK2: 2.0087899 | CL2: None | CM2: 0 | CN2: None | CO2: 0 | CP2: None | CQ2: 0 | CR2: None | CS2: 0 | CT2: 0.1239786 | CU2: 8.0659081 | CV2: 0.084 | CW2: 0 | CX2: 0.047 | CY2: 0.053 | CZ2: 0.04 | DA2: 0.062166147 | DB2: 0.651 | DC2: 0.252 | DD2: 0.319 | DE2: 1.265873 | DF2: 0 | DG2: 0.54 | DH2: 0.54 | DI2: 109.2 | DJ2: 109.2 | DK2: 0.69 | DL2: 0.69 | DM2: 1672 | DN2: 0.122 | DO2: 10601 | DP2: 0.777 | DQ2: 10601 | DR2: 0.777 | DS2: 0 | DT2: 0 | DU2: 0 | DV2: 0 | DW2: 0 | DX2: 0 | DY2: 6.88 | DZ2: 0 | EA2: 0 | EB2: 0
A3: ASHRAE 90.1-2010 Baseline 90° | B3: Casa De Amparo_v4z 1.pdf | C3: Jun 11, 2026 - 10:50 PM | D3: ASHRAE 90.1-2010 BASELINE ** Climate Zone 10 CA USA CTZRV2 WMO#=722860 | E3: 3B | F3: 50 | G3: 1565 | H3: 696000 | I3: 50.98 | J3: 695833.04 | K3: 0 | L3: 0 | M3: 0 | N3: 0 | O3: 38006.268 | P3: 0 | Q3: 0 | R3: 0 | S3: 145037.3 | T3: 0 | U3: 153372.81 | V3: 0 | W3: 180081.95 | X3: 0 | Y3: 0 | Z3: 0 | AA3: 179334.72 | AB3: 0 | AC3: 0 | AD3: 0 | AE3: 0 | AF3: 0 | AG3: 0 | AH3: 0 | AI3: 0 | AJ3: 0 | AK3: 0 | AL3: 0 | AM3: 0 | AN3: 0 | AO3: 0 | AP3: 0 | AQ3: 0 | AR3: 0 | AS3: 25385.3 | AT3: 1.8594565 | AU3: 0.036342321 | AV3: 0 | AW3: 0 | AX3: 0 | AY3: 0 | AZ3: 82390.548 | BA3: 6.0350533 | BB3: 0.11840563 | BC3: 0.053 | BD3: 0 | BE3: 0 | BF3: 0 | BG3: 786 | BH3: 57.6 | BJ3: 360 | BK3: 26.4 | BM3: 49000 | BN3: 3.6 | BP3: 13652 | BQ3: 21103 | BR3: 11729 | BS3: 11729 | BT3: 2721 | BU3: 2651 | BV3: 3382 | BW3: 2975 | BX3: 8.2 | BY3: 10.4 | BZ3: 5.1 | CA3: 5.2 | CB3: 7.05 | CC3: 8.2322675 | CD3: 10.448887 | CE3: 5.0561798 | CF3: 5.210084 | CG3: 15695 | CH3: 0 | CI3: 0.85914152 | CJ3: 1.1496484 | CK3: 2.0087899 | CL3: None | CM3: 0 | CN3: None | CO3: 0 | CP3: None | CQ3: 0 | CR3: None | CS3: 0 | CT3: 0.1239786 | CU3: 8.0659081 | CV3: 0.084 | CW3: 0 | CX3: 0.047 | CY3: 0.053 | CZ3: 0.04 | DA3: 0.062166147 | DB3: 0.651 | DC3: 0.252 | DD3: 0.319 | DE3: 1.265873 | DF3: 0 | DG3: 0.54 | DH3: 0.54 | DI3: 109.2 | DJ3: 109.2 | DK3: 0.69 | DL3: 0.69 | DM3: 1672 | DN3: 0.122 | DO3: 10601 | DP3: 0.777 | DQ3: 10601 | DR3: 0.777 | DS3: 0 | DT3: 0 | DU3: 0 | DV3: 0 | DW3: 0 | DX3: 0 | DY3: 6.88 | DZ3: 0 | EA3: 0 | EB3: 0
A4: ASHRAE 90.1-2010 Baseline 180° | B4: Casa De Amparo_v4z 1.pdf | C4: Jun 11, 2026 - 10:50 PM | D4: ASHRAE 90.1-2010 BASELINE ** Climate Zone 10 CA USA CTZRV2 WMO#=722860 | E4: 3B | F4: 50 | G4: 1565 | H4: 686000 | I4: 50.25 | J4: 685835.88 | K4: 0 | L4: 0 | M4: 0 | N4: 0 | O4: 39261.884 | P4: 0 | Q4: 0 | R4: 0 | S4: 140536.87 | T4: 0 | U4: 153372.81 | V4: 0 | W4: 180081.95 | X4: 0 | Y4: 0 | Z4: 0 | AA4: 172582.37 | AB4: 0 | AC4: 0 | AD4: 0 | AE4: 0 | AF4: 0 | AG4: 0 | AH4: 0 | AI4: 0 | AJ4: 0 | AK4: 0 | AL4: 0 | AM4: 0 | AN4: 0 | AO4: 0 | AP4: 0 | AQ4: 0 | AR4: 0 | AS4: 25385.3 | AT4: 1.8594565 | AU4: 0.036342321 | AV4: 0 | AW4: 0 | AX4: 0 | AY4: 0 | AZ4: 81206.828 | BA4: 5.9483466 | BB4: 0.11840563 | BC4: 0.053 | BD4: 0 | BE4: 0 | BF4: 0 | BG4: 786 | BH4: 57.6 | BJ4: 360 | BK4: 26.4 | BM4: 49000 | BN4: 3.6 | BP4: 13652 | BQ4: 21103 | BR4: 11729 | BS4: 11729 | BT4: 2721 | BU4: 2651 | BV4: 3382 | BW4: 2975 | BX4: 8.2 | BY4: 10.4 | BZ4: 5.1 | CA4: 5.2 | CB4: 7.05 | CC4: 8.2322675 | CD4: 10.448887 | CE4: 5.0561798 | CF4: 5.210084 | CG4: 15695 | CH4: 0 | CI4: 0.85914152 | CJ4: 1.1496484 | CK4: 2.0087899 | CL4: None | CM4: 0 | CN4: None | CO4: 0 | CP4: None | CQ4: 0 | CR4: None | CS4: 0 | CT4: 0.1239786 | CU4: 8.0659081 | CV4: 0.084 | CW4: 0 | CX4: 0.047 | CY4: 0.053 | CZ4: 0.04 | DA4: 0.062166147 | DB4: 0.651 | DC4: 0.252 | DD4: 0.319 | DE4: 1.265873 | DF4: 0 | DG4: 0.54 | DH4: 0.54 | DI4: 109.2 | DJ4: 109.2 | DK4: 0.69 | DL4: 0.69 | DM4: 1672 | DN4: 0.122 | DO4: 10601 | DP4: 0.777 | DQ4: 10601 | DR4: 0.777 | DS4: 0 | DT4: 0 | DU4: 0 | DV4: 0 | DW4: 0 | DX4: 0 | DY4: 6.88 | DZ4: 0 | EA4: 0 | EB4: 0
A5: ASHRAE 90.1-2010 Baseline 270° | B5: Casa De Amparo_v4z 1.pdf | C5: Jun 11, 2026 - 10:50 PM | D5: ASHRAE 90.1-2010 BASELINE ** Climate Zone 10 CA USA CTZRV2 WMO#=722860 | E5: 3B | F5: 50 | G5: 1565 | H5: 683000 | I5: 50.03 | J5: 683041.46 | K5: 0 | L5: 0 | M5: 0 | N5: 0 | O5: 38579.484 | P5: 0 | Q5: 0 | R5: 0 | S5: 140864.42 | T5: 0 | U5: 153372.81 | V5: 0 | W5: 180081.95 | X5: 0 | Y5: 0 | Z5: 0 | AA5: 170142.79 | AB5: 0 | AC5: 0 | AD5: 0 | AE5: 0 | AF5: 0 | AG5: 0 | AH5: 0 | AI5: 0 | AJ5: 0 | AK5: 0 | AL5: 0 | AM5: 0 | AN5: 0 | AO5: 0 | AP5: 0 | AQ5: 0 | AR5: 0 | AS5: 25385.3 | AT5: 1.8594565 | AU5: 0.036342321 | AV5: 0 | AW5: 0 | AX5: 0 | AY5: 0 | AZ5: 80875.952 | BA5: 5.9241102 | BB5: 0.11840563 | BC5: 0.053 | BD5: 0 | BE5: 0 | BF5: 0 | BG5: 786 | BH5: 57.6 | BJ5: 360 | BK5: 26.4 | BM5: 49000 | BN5: 3.6 | BP5: 13652 | BQ5: 21103 | BR5: 11729 | BS5: 11729 | BT5: 2721 | BU5: 2651 | BV5: 3382 | BW5: 2975 | BX5: 8.2 | BY5: 10.4 | BZ5: 5.1 | CA5: 5.2 | CB5: 7.05 | CC5: 8.2322675 | CD5: 10.448887 | CE5: 5.0561798 | CF5: 5.210084 | CG5: 15695 | CH5: 0 | CI5: 0.85914152 | CJ5: 1.1496484 | CK5: 2.0087899 | CL5: None | CM5: 0 | CN5: None | CO5: 0 | CP5: None | CQ5: 0 | CR5: None | CS5: 0 | CT5: 0.1239786 | CU5: 8.0659081 | CV5: 0.084 | CW5: 0 | CX5: 0.047 | CY5: 0.053 | CZ5: 0.04 | DA5: 0.062166147 | DB5: 0.651 | DC5: 0.252 | DD5: 0.319 | DE5: 1.265873 | DF5: 0 | DG5: 0.54 | DH5: 0.54 | DI5: 109.2 | DJ5: 109.2 | DK5: 0.69 | DL5: 0.69 | DM5: 1672 | DN5: 0.122 | DO5: 10601 | DP5: 0.777 | DQ5: 10601 | DR5: 0.777 | DS5: 0 | DT5: 0 | DU5: 0 | DV5: 0 | DW5: 0 | DX5: 0 | DY5: 6.88 | DZ5: 0 | EA5: 0 | EB5: 0

Sheet Proposed Data
A1: Option | B1: Results Path | C1: Timestamp | D1: Climate File | E1: Climate Zone | F1: Heating Unmet Hours | G1: Cooling Unmet Hours | H1: =_xlfn.CONCAT("Total Energy Use ",IF('Project Info'!$I$4=Menus!$A$2,"(kWh)","(kBtu)")) -> Total Energy Use (kBtu) | I1: =_xlfn.CONCAT("Energy Use Intensity ",IF('Project Info'!$I$4=Menus!$A$2,"(kWh/m²)","(kBtu/ft²)")) -> Energy Use Intensity (kBtu/ft²) | J1: =_xlfn.CONCAT("Electricity ",IF('Project Info'!$I$4=Menus!$A$2,"(kWh)","(kBtu)")) -> Electricity (kBtu) | K1: =_xlfn.CONCAT("Gas ",IF('Project Info'!$I$4=Menus!$A$2,"(kWh)","(kBtu)")) -> Gas (kBtu) | L1: =_xlfn.CONCAT("Additional Fuel ",IF('Project Info'!$I$4=Menus!$A$2,"(kWh)","(kBtu)")) -> Additional Fuel (kBtu) | M1: =_xlfn.CONCAT("District Cooling ",IF('Project Info'!$I$4=Menus!$A$2,"(kWh)","(kBtu)")) -> District Cooling (kBtu) | N1: =_xlfn.CONCAT("District Heating ",IF('Project Info'!$I$4=Menus!$A$2,"(kWh)","(kBtu)")) -> District Heating (kBtu) | O1: =_xlfn.CONCAT("Heating - Electricity Energy Use ",IF('Project Info'!$I$4=Menus!$A$2,"(kWh)","(kBtu)")) -> Heating - Electricity Energy Use (kBtu) | P1: =_xlfn.CONCAT("Heating - Gas Energy Use ",IF('Project Info'!$I$4=Menus!$A$2,"(kWh)","(kBtu)")) -> Heating - Gas Energy Use (kBtu) | Q1: =_xlfn.CONCAT("Heating - Additonal Fuel Energy Use ",IF('Project Info'!$I$4=Menus!$A$2,"(kWh)","(kBtu)")) -> Heating - Additonal Fuel Energy Use (kBtu) | R1: =_xlfn.CONCAT("Heating - District Heating Energy Use ",IF('Project Info'!$I$4=Menus!$A$2,"(kWh)","(kBtu)")) -> Heating - District Heating Energy Use (kBtu) | S1: =_xlfn.CONCAT("Cooling - Electricity Energy Use ",IF('Project Info'!$I$4=Menus!$A$2,"(kWh)","(kBtu)")) -> Cooling - Electricity Energy Use (kBtu) | T1: =_xlfn.CONCAT("Cooling - District Energy Use ",IF('Project Info'!$I$4=Menus!$A$2,"(kWh)","(kBtu)")) -> Cooling - District Energy Use (kBtu) | U1: =_xlfn.CONCAT("Interior Lighting - Electricity Energy Use ",IF('Project Info'!$I$4=Menus!$A$2,"(kWh)","(kBtu)")) -> Interior Lighting - Electricity Energy Use (kBtu) | V1: =_xlfn.CONCAT("Exterior Lighting - Electricity Energy Use ",IF('Project Info'!$I$4=Menus!$A$2,"(kWh)","(kBtu)")) -> Exterior Lighting - Electricity Energy Use (kBtu) | W1: =_xlfn.CONCAT("Interior Equipment - Electricity Energy Use ",IF('Project Info'!$I$4=Menus!$A$2,"(kWh)","(kBtu)")) -> Interior Equipment - Electricity Energy Use (kBtu) | X1: =_xlfn.CONCAT("Interior Equipment - Gas Energy Use ",IF('Project Info'!$I$4=Menus!$A$2,"(kWh)","(kBtu)")) -> Interior Equipment - Gas Energy Use (kBtu) | Y1: =_xlfn.CONCAT("Interior Equipment - Additional Fuel Energy Use ",IF('Project Info'!$I$4=Menus!$A$2,"(kWh)","(kBtu)")) -> Interior Equipment - Additional Fuel Energy Use (kBtu) | Z1: =_xlfn.CONCAT("Exterior Equipment - Energy Use ",IF('Project Info'!$I$4=Menus!$A$2,"(kWh)","(kBtu)")) -> Exterior Equipment - Energy Use (kBtu) | AA1: =_xlfn.CONCAT("Fans - Electricity Energy Use ",IF('Project Info'!$I$4=Menus!$A$2,"(kWh)","(kBtu)")) -> Fans - Electricity Energy Use (kBtu) | AB1: =_xlfn.CONCAT("Pumps - Electricity Energy Use ",IF('Project Info'!$I$4=Menus!$A$2,"(kWh)","(kBtu)")) -> Pumps - Electricity Energy Use (kBtu) | AC1: =_xlfn.CONCAT("Heat Rejection - Electricity Energy Use ",IF('Project Info'!$I$4=Menus!$A$2,"(kWh)","(kBtu)")) -> Heat Rejection - Electricity Energy Use (kBtu) | AD1: =_xlfn.CONCAT("Humidification - Electricity Energy Use ",IF('Project Info'!$I$4=Menus!$A$2,"(kWh)","(kBtu)")) -> Humidification - Electricity Energy Use (kBtu) | AE1: =_xlfn.CONCAT("Heat Recovery - Electricity Energy Use ",IF('Project Info'!$I$4=Menus!$A$2,"(kWh)","(kBtu)")) -> Heat Recovery - Electricity Energy Use (kBtu) | AF1: =_xlfn.CONCAT("Water Systems - Electricity Energy Use ",IF('Project Info'!$I$4=Menus!$A$2,"(kWh)","(kBtu)")) -> Water Systems - Electricity Energy Use (kBtu) | AG1: =_xlfn.CONCAT("Water Systems - Gas Energy Use ",IF('Project Info'!$I$4=Menus!$A$2,"(kWh)","(kBtu)")) -> Water Systems - Gas Energy Use (kBtu) | AH1: =_xlfn.CONCAT("Water Systems - Additional Fuel Energy Use ",IF('Project Info'!$I$4=Menus!$A$2,"(kWh)","(kBtu)")) -> Water Systems - Additional Fuel Energy Use (kBtu) | AI1: =_xlfn.CONCAT("Water Systems - District Heating Energy Use ",IF('Project Info'!$I$4=Menus!$A$2,"(kWh)","(kBtu)")) -> Water Systems - District Heating Energy Use (kBtu) | AJ1: =_xlfn.CONCAT("Refrigeration - Electricity Energy Use ",IF('Project Info'!$I$4=Menus!$A$2,"(kWh)","(kBtu)")) -> Refrigeration - Electricity Energy Use (kBtu) | AK1: =_xlfn.CONCAT("Generators Electricity Energy Use ",IF('Project Info'!$I$4=Menus!$A$2,"(kWh)","(kBtu)")) -> Generators Electricity Energy Use (kBtu) | AL1: =_xlfn.CONCAT("Misc 1 - Electricity Energy Use ",IF('Project Info'!$I$4=Menus!$A$2,"(kWh)","(kBtu)")) -> Misc 1 - Electricity Energy Use (kBtu) | AM1: =_xlfn.CONCAT("Misc 2 - Electricity Energy Use ",IF('Project Info'!$I$4=Menus!$A$2,"(kWh)","(kBtu)")) -> Misc 2 - Electricity Energy Use (kBtu) | AN1: =_xlfn.CONCAT("Total Water Use ",IF('Project Info'!$I$4=Menus!$A$2,"(m3)","(kGal)")) -> Total Water Use (kGal) | AO1: =_xlfn.CONCAT("Water Use Intensity ",IF('Project Info'!$I$4=Menus!$A$2,"(m³/m²)","(kGal/ft²)")) -> Water Use Intensity (kGal/ft²) | AP1: =_xlfn.CONCAT("Heat Rejection - Water Use ",IF('Project Info'!$I$4=Menus!$A$2,"(m3)","(kGal)")) -> Heat Rejection - Water Use (kGal) | AQ1: =_xlfn.CONCAT("Humidificatopn - Water Use ",IF('Project Info'!$I$4=Menus!$A$2,"(m3)","(kGal)")) -> Humidificatopn - Water Use (kGal) | AR1: =_xlfn.CONCAT("Water System - Water Use ",IF('Project Info'!$I$4=Menus!$A$2,"(m3)","(kGal)")) -> Water System - Water Use (kGal) | AS1: Total Energy Cost ($) | AT1: =_xlfn.CONCAT("Energy Cost Intensity (",IF('Project Info'!$I$4=Menus!$A$2,Menus!$E$10,Menus!$E$11),")") -> Energy Cost Intensity ($/ft²) | AU1: =_xlfn.CONCAT("Electricity Virtual Rate (",IF('Project Info'!$I$4=Menus!$A$2,Menus!$E$14,Menus!$E$15),")") -> Electricity Virtual Rate ($/kBtu) | AV1: =_xlfn.CONCAT("Gas Virtual Rate (",IF('Project Info'!$I$4=Menus!$A$2,Menus!$E$14,Menus!$E$15),")") -> Gas Virtual Rate ($/kBtu) | AW1: =_xlfn.CONCAT("Additional Fuel Virtual Rate (",IF('Project Info'!$I$4=Menus!$A$2,Menus!$E$14,Menus!$E$15),")") -> Additional Fuel Virtual Rate ($/kBtu) | AX1: =_xlfn.CONCAT("District Cooling Virtual Rate (",IF('Project Info'!$I$4=Menus!$A$2,Menus!$E$14,Menus!$E$15),")") -> District Cooling Virtual Rate ($/kBtu) | AY1: =_xlfn.CONCAT("District Heating Virtual Rate (",IF('Project Info'!$I$4=Menus!$A$2,Menus!$E$14,Menus!$E$15),")") -> District Heating Virtual Rate ($/kBtu) | AZ1: =_xlfn.CONCAT("Total Carbon Emissions (",IF('Project Info'!$I$4=Menus!$A$2,Menus!$G$6,Menus!$G$7),")") -> Total Carbon Emissions (kg CO2e) | BA1: =_xlfn.CONCAT("Carbon Emission Intensity (",IF('Project Info'!$I$4=Menus!$A$2,Menus!$G$10,Menus!$G$11),")") -> Carbon Emission Intensity (kg CO2e/ft²) | BB1: =_xlfn.CONCAT("Electricity Virtual Rate (",IF('Project Info'!$I$4=Menus!$A$2,Menus!$G$14,Menus!$G$15),")") -> Electricity Virtual Rate (kg CO2e/kBtu) | BC1: =_xlfn.CONCAT("Gas Virtual Rate (",IF('Project Info'!$I$4=Menus!$A$2,Menus!$G$14,Menus!$G$15),")") -> Gas Virtual Rate (kg CO2e/kBtu) | BD1: =_xlfn.CONCAT("Additional Fuel Virtual Rate (",IF('Project Info'!$I$4=Menus!$A$2,Menus!$G$14,Menus!$G$15),")") -> Additional Fuel Virtual Rate (kg CO2e/kBtu) | BE1: =_xlfn.CONCAT("District Cooling Virtual Rate (",IF('Project Info'!$I$4=Menus!$A$2,Menus!$G$14,Menus!$G$15),")") -> District Cooling Virtual Rate (kg CO2e/kBtu) | BF1: =_xlfn.CONCAT("District Heating Virtual Rate (",IF('Project Info'!$I$4=Menus!$A$2,Menus!$G$14,Menus!$G$15),")") -> District Heating Virtual Rate (kg CO2e/kBtu) | BG1: =_xlfn.CONCAT("Peak Heating ",IF('Project Info'!$I$4=Menus!$A$2,"(kW)","(kBtuh)")) -> Peak Heating (kBtuh) | BH1: =_xlfn.CONCAT("Peak Heating ",IF('Project Info'!$I$4=Menus!$A$2,"(W/m²)","(Btuh/ft²)")) -> Peak Heating (Btuh/ft²) | BI1: Peak Heating Hour | BJ1: =_xlfn.CONCAT("Peak Cooling ",IF('Project Info'!$I$4=Menus!$A$2,"(kW)","(kBtuh)")) -> Peak Cooling (kBtuh) | BK1: =_xlfn.CONCAT("Peak Cooling ",IF('Project Info'!$I$4=Menus!$A$2,"(W/m²)","(Btuh/ft²)")) -> Peak Cooling (Btuh/ft²) | BL1: Peak Cooling Hour | BM1: Peak Electrical Load (W) | BN1: =_xlfn.CONCAT("Peak Electrical Load Intensity ",IF('Project Info'!$I$4=Menus!$A$2,"(W/m²)","(W/ft²)")) -> Peak Electrical Load Intensity (W/ft²) | BO1: Peak Electricity Hour | BP1: =_xlfn.CONCAT("Conditioned Floor Area ",IF('Project Info'!$I$4=Menus!$A$2,"(m²)","(ft²)")) -> Conditioned Floor Area (ft²) | BQ1: =_xlfn.CONCAT("Total Floor Area ",IF('Project Info'!$I$4=Menus!$A$2,"(m²)","(ft²)")) -> Total Floor Area (ft²) | BR1: =_xlfn.CONCAT("Gross Wall Area ",IF('Project Info'!$I$4=Menus!$A$2,"(m²)","(ft²)")) -> Gross Wall Area (ft²) | BS1: =_xlfn.CONCAT("Above Ground Gross Wall Area ",IF('Project Info'!$I$4=Menus!$A$2,"(m²)","(ft²)")) -> Above Ground Gross Wall Area (ft²) | BT1: =_xlfn.CONCAT("Above Ground North Wall Area ",IF('Project Info'!$I$4=Menus!$A$2,"(m²)","(ft²)")) -> Above Ground North Wall Area (ft²) | BU1: =_xlfn.CONCAT("Above Ground East Wall Area ",IF('Project Info'!$I$4=Menus!$A$2,"(m²)","(ft²)")) -> Above Ground East Wall Area (ft²) | BV1: =_xlfn.CONCAT("Above Ground South Wall Area ",IF('Project Info'!$I$4=Menus!$A$2,"(m²)","(ft²)")) -> Above Ground South Wall Area (ft²) | BW1: =_xlfn.CONCAT("Above Ground East Wall Area ",IF('Project Info'!$I$4=Menus!$A$2,"(m²)","(ft²)")) -> Above Ground East Wall Area (ft²) | BX1: North WWR Nominal (%) | BY1: East WWR Nominal (%) | BZ1: South WWR Nominal (%) | CA1: West WWR Nominal (%) | CB1: Building WWR Actual (%) | CC1: North WWR Actual (%) | CD1: East WWR Actual (%) | CE1: South WWR Actual (%) | CF1: West WWR Actual (%) | CG1: =_xlfn.CONCAT("Gross Roof Area ",IF('Project Info'!$I$4=Menus!$A$2,"(m²)","(ft²)")) -> Gross Roof Area (ft²) | CH1: Skylight Roof Ratio (%) | CI1: Exterior Wall to Floor Area Ratio | CJ1: Exterior Roof to Floor Area Ratio | CK1: Exterior Envelope to Floor Area Ratio | CL1: North Shading Type | CM1: North Shading Ratio (%) | CN1: West Shading Type | CO1: West Shading Ratio (%) | CP1: South Shading Type | CQ1: South Shading Ratio (%) | CR1: East Shading Type | CS1: East Shading Ratio (%) | CT1: =_xlfn.CONCAT("Vertical Weighted U-Value ",IF('Project Info'!$D$7=Menus!$C$2,"(W/m²·K)","(Btu/h·ft²·F)")) -> Vertical Weighted U-Value (Btu/h·ft²·F) | CU1: =_xlfn.CONCAT("Vertical Weighted R-Value ",IF('Project Info'!$D$7=Menus!$C$2,"(m²·K/W)","(ft²·h·F/Btu )")) -> Vertical Weighted R-Value (ft²·h·F/Btu ) | CV1: =_xlfn.CONCAT("Wall U-Value ",IF('Project Info'!$D$7=Menus!$C$2,"(W/m²·K)","(Btu/h·ft²·F)")) -> Wall U-Value (Btu/h·ft²·F) | CW1: =_xlfn.CONCAT("Wall 2 U-Value ",IF('Project Info'!$D$7=Menus!$C$2,"(W/m²·K)","(Btu/h·ft²·F)")) -> Wall 2 U-Value (Btu/h·ft²·F) | CX1: =_xlfn.CONCAT("Roof U-Value ",IF('Project Info'!$D$7=Menus!$C$2,"(W/m²·K)","(Btu/h·ft²·F)")) -> Roof U-Value (Btu/h·ft²·F) | CY1: =_xlfn.CONCAT("Exposed Floor U-Value ",IF('Project Info'!$D$7=Menus!$C$2,"(W/m²·K)","(Btu/h·ft²·F)")) -> Exposed Floor U-Value (Btu/h·ft²·F) | CZ1: =_xlfn.CONCAT("Slab on Grade U-Value ",IF('Project Info'!$D$7=Menus!$C$2,"(W/m²·K)","(Btu/h·ft²·F)")) -> Slab on Grade U-Value (Btu/h·ft²·F) | DA1: =_xlfn.CONCAT("Assembly U-Value ",IF('Project Info'!$D$7=Menus!$C$2,"(W/m²·K)","(Btu/h·ft²·F)")) -> Assembly U-Value (Btu/h·ft²·F) | DB1: =_xlfn.CONCAT("Glass U-Value ",IF('Project Info'!$D$7=Menus!$C$2,"(W/m²·K)","(Btu/h·ft²·F)")) -> Glass U-Value (Btu/h·ft²·F) | DC1: Glass SHGC | DD1: Glass VLT | DE1: Glass LSG | DF1: =_xlfn.CONCAT("Infiltration Rate ",IF('Project Info'!$D$7=Menus!$C$2,"(m³/s/m² façade)","(CFM/ft² facade)")) -> Infiltration Rate (CFM/ft² facade) | DG1: =_xlfn.CONCAT("Lighting Power Density ",IF('Project Info'!$D$7=Menus!$C$2,"(W/m²)","(W/ft²)")) -> Lighting Power Density (W/ft²) | DH1: =_xlfn.CONCAT("Conditioned Lighting Power Density ",IF('Project Info'!$D$7=Menus!$C$2,"(W/m²)","(W/ft²)")) -> Conditioned Lighting Power Density (W/ft²) | DI1: =_xlfn.CONCAT("Occupant Density ",IF('Project Info'!$D$7=Menus!$C$2,"(m/person²)","(ft²/person)")) -> Occupant Density (ft²/person) | DJ1: =_xlfn.CONCAT("Conditioned Occupant Density ",IF('Project Info'!$D$7=Menus!$C$2,"(m/person²)","(ft²/person)")) -> Conditioned Occupant Density (ft²/person) | DK1: =_xlfn.CONCAT("Equipment Power Density ",IF('Project Info'!$D$7=Menus!$C$2,"(W/m²)","(W/ft²)")) -> Equipment Power Density (W/ft²) | DL1: =_xlfn.CONCAT("Conditioned Equipment Power Density ",IF('Project Info'!$D$7=Menus!$C$2,"(W/m²)","(W/ft²)")) -> Conditioned Equipment Power Density (W/ft²) | DM1: =_xlfn.CONCAT("Total Ventilation Air Flow Rate ",IF('Project Info'!$D$7=Menus!$C$2,"(m²/s)","(CFM)")) -> Total Ventilation Air Flow Rate (CFM) | DN1: =_xlfn.CONCAT("Ventilation Air Flow Rate per Area ",IF('Project Info'!$D$7=Menus!$C$2,"(m3/s/m²)","(CFM/ft²)")) -> Ventilation Air Flow Rate per Area (CFM/ft²) | DO1: =_xlfn.CONCAT("Total Heating Airflow Rate ",IF('Project Info'!$D$7=Menus!$C$2,"(m²/s)","(CFM)")) -> Total Heating Airflow Rate (CFM) | DP1: =_xlfn.CONCAT("Heating Airflow Rate per Area ",IF('Project Info'!$D$7=Menus!$C$2,"(m3/s/m²)","(CFM/ft²)")) -> Heating Airflow Rate per Area (CFM/ft²) | DQ1: =_xlfn.CONCAT("Total Cooling Airflow Rate ",IF('Project Info'!$D$7=Menus!$C$2,"(m²/s)","(CFM)")) -> Total Cooling Airflow Rate (CFM) | DR1: =_xlfn.CONCAT("Cooling Airflow Rate per Area ",IF('Project Info'!$D$7=Menus!$C$2,"(m3/s/m²)","(CFM/ft²)")) -> Cooling Airflow Rate per Area (CFM/ft²) | DS1: Chiller Efficiency (COP) | DT1: Boiler Efficiency (COP) | DU1: DX Cooling Efficiency (COP) | DV1: DX Heating Efficiency (HSPF) | DW1: Heat Pump Cooling Efficiency (COP) | DX1: Heat Pump Heating Efficiency (COP) | DY1: Total Fan Power (kW) | DZ1: Total Pump Power (kW) | EA1: Service Hot Water Thermal Efficiency (COP) | EB1: Exterior Lighting (kW)
A2: Primary 0° | B2: Casa De Amparo_v4z 1.pdf | C2: Jun 11, 2026 - 10:50 PM | D2: ASHRAE 90.1-2010 BASELINE ** Climate Zone 10 CA USA CTZRV2 WMO#=722860 | E2: 3B | F2: 105 | G2: 547 | H2: 689500 | I2: 50.505 | J2: 689470.52 | K2: 0 | L2: 0 | M2: 0 | N2: 0 | O2: 38337.232 | P2: 0 | Q2: 0 | R2: 0 | S2: 142882.62 | T2: 0 | U2: 153372.81 | V2: 0 | W2: 180081.95 | X2: 0 | Y2: 0 | Z2: 0 | AA2: 174795.91 | AB2: 0 | AC2: 0 | AD2: 0 | AE2: 0 | AF2: 0 | AG2: 0 | AH2: 0 | AI2: 0 | AJ2: 0 | AK2: 0 | AL2: 0 | AM2: 0 | AN2: 0 | AO2: 0 | AP2: 0 | AQ2: 0 | AR2: 0 | AS2: 26967.79 | AT2: 1.9753728 | AU2: 0.036342321 | AV2: 0 | AW2: 0 | AX2: 0 | AY2: 0 | AZ2: 81637.189 | BA2: 5.9798703 | BB2: 0.11840563 | BC2: 0.053 | BD2: 0 | BE2: 0 | BF2: 0 | BG2: 410 | BH2: 30 | BJ2: 300 | BK2: 22 | BM2: 53000 | BN2: 3.9 | BP2: 13652 | BQ2: 21103 | BR2: 11729 | BS2: 11729 | BT2: 2721 | BU2: 2651 | BV2: 3382 | BW2: 2975 | BX2: 8.2 | BY2: 10.4 | BZ2: 5.1 | CA2: 5.2 | CB2: 7.05 | CC2: 8.2322675 | CD2: 10.448887 | CE2: 5.0561798 | CF2: 5.210084 | CG2: 15695 | CH2: 0 | CI2: 0.85914152 | CJ2: 1.1496484 | CK2: 2.0087899 | CL2: None | CM2: 0 | CN2: None | CO2: 0 | CP2: None | CQ2: 0 | CR2: None | CS2: 0 | CT2: 0.078081593 | CU2: 12.807116 | CV2: 0.046 | CW2: 0 | CX2: 0.026 | CY2: 0.038 | CZ2: 0.041 | DA2: 0.034197917 | DB2: 0.501 | DC2: 0.401 | DD2: 0.442 | DE2: 1.1022444 | DF2: 0 | DG2: 0.45 | DH2: 0.45 | DI2: 109.2 | DJ2: 109.2 | DK2: 0.69 | DL2: 0.69 | DM2: 1550 | DN2: 0.114 | DO2: 4082 | DP2: 0.299 | DQ2: 8767 | DR2: 0.642 | DS2: 0 | DT2: 0 | DU2: 0 | DV2: 0 | DW2: 0 | DX2: 0 | DY2: 0 | DZ2: 0 | EA2: 0 | EB2: 0

Sheet LEED BL
A1: LEED Baseline Results Worksheet
B3: Instructions
B4: If the 'BL Data' tab has been populated with the LEED and Code baseline rotations by a script, use the pulldowns next to the 'Baseline Case' to choose if only the 0 degree rotation or the average of all rotations should be used. The results will automatically be pulled in from the database. Use the input cells to manually input values without using the database, or to override or add to database values.
B7: =IF($C$10=Menus!$I$2,$A$1,_xlfn.CONCAT($A$1," 0° Rotation")) -> LEED Baseline Results Worksheet 0° Rotation
B9: =IF(AND(C10=Menus!$I$3,OR(Z24=0,Z38=0,Z52=0)),"Missing baseline rotations. Set to '"&Menus!$I$2&"'"," ") | G9: Case Name | I9: Result File Path and Name | O9: Timestamp | R9: Peak Electrical Demand | Y9: Energy Results
B10: Baseline Case | F10: Imported Data | G10: ='BL Data'!A2 -> ASHRAE 90.1-2010 Baseline 0° | I10: ='BL Data'!B2 -> Casa De Amparo_v4z 1.pdf | O10: ='BL Data'!C2 -> Jun 11, 2026 - 10:50 PM | R10: ='BL Data'!BM2/1000 -> 49 | S10: kW | Y10: Total | Z10: =SUM(C19:AA19) -> 693171.68 | AA10: ='Project Info'!$I$5 -> kBtu
B11: Area | C11: =IFERROR(IF(ISBLANK('Project Info'!$D$7),'BL Data'!BP2,'Project Info'!$D$7),0) -> 13652 | D11: =IF($I$11="SI","m²","ft²") -> ft² | F11: Manual Input | G11: LEED Baseline | S11: kW | Z11: =IFERROR(Z10/$C$11,0) -> 50.774369 | AA11: =IF('Project Info'!$I$4=Menus!$A$2,"kWh/m²","kBtu/ft²") -> kBtu/ft²
F12: Value Used | G12: =IF(ISBLANK(G11),IF(G10=0,"LEED Baseline",G10),G11) -> LEED Baseline | I12: =IF(ISBLANK(I11),I10,I11) -> Casa De Amparo_v4z 1.pdf | O12: =IF(ISBLANK(O11),O10,O11) -> Jun 11, 2026 - 10:50 PM | R12: =IF(ISBLANK(R11),R10,R11) -> 49 | S12: kW
B14: End Use | C14: Heating | G14: Cooling | I14: Lighting | J14: Exterior Lighting | K14: Equipment | N14: Exterior Equipment | O14: Fans | P14: Pumps | Q14: Heat Rejection | R14: Humidification | S14: Heat Recovery | T14: Water Systems | X14: Refrigeration | Y14: Generators | Z14: ='Project Info'!$I$10 -> 0 | AA14: ='Project Info'!$J$10 -> 0
B15: Fuel Source | C15: Electricity | D15: Gas | E15: Additional Fuel | F15: District Heating | G15: Electricity | H15: District Cooling | I15: Electricity | J15: Electricity | K15: Electricity | L15: Gas | M15: Additional Fuel | N15: Electricity | O15: Electricity | P15: Electricity | Q15: Electricity | R15: Electricity | S15: Electricity | T15: Electricity | U15: Gas | V15: Additional Fuel | W15: District Heating | X15: Electricity | Y15: Electricity | Z15: Electricity | AA15: Electricity
B16: Input Units | C16: ='Project Info'!$I$5 -> kBtu | D16: ='Project Info'!$I$5 -> kBtu | E16: ='Project Info'!$I$5 -> kBtu | F16: ='Project Info'!$I$5 -> kBtu | G16: ='Project Info'!$I$5 -> kBtu | H16: ='Project Info'!$I$5 -> kBtu | I16: ='Project Info'!$I$5 -> kBtu | J16: ='Project Info'!$I$5 -> kBtu | ... AA16: ='Project Info'!$I$5 -> kBtu
B17: Imported Data | C17: ='BL Data'!O2 -> 37501.292 | D17: ='BL Data'!P2 -> 0 | E17: ='BL Data'!Q2 -> 0 | F17: ='BL Data'!R2 -> 0 | G17: ='BL Data'!S2 -> 145091.89 | H17: ='BL Data'!T2 -> 0 | I17: ='BL Data'!U2 -> 153372.81 | J17: ='BL Data'!V2 -> 0 | ... AA17: ='BL Data'!AM2 -> 0
B18: Manual Input
B19: Value Used | C19: =IF(ISBLANK(C18),C17,C18) -> 37501.292 | D19: =IF(ISBLANK(D18),D17,D18) -> 0 | E19: =IF(ISBLANK(E18),E17,E18) -> 0 | F19: =IF(ISBLANK(F18),F17,F18) -> 0 | G19: =IF(ISBLANK(G18),G17,G18) -> 145091.89 | H19: =IF(ISBLANK(H18),H17,H18) -> 0 | I19: =IF(ISBLANK(I18),I17,I18) -> 153372.81 | J19: =IF(ISBLANK(J18),J17,J18) -> 0 | ... AA19: =IF(ISBLANK(AA18),AA17,AA18) -> 0
B21: =IF($C$10=Menus!$I$2,"N/A",_xlfn.CONCAT($A$1," 90° Rotation")) -> LEED Baseline Results Worksheet 90° Rotation
G23: Case Name | I23: Result File Path and Name | O23: Timestamp | R23: Peak Electrical Demand | Y23: Energy Results
F24: Imported Data | G24: ='BL Data'!A3 -> ASHRAE 90.1-2010 Baseline 90° | I24: ='BL Data'!B3 -> Casa De Amparo_v4z 1.pdf | O24: ='BL Data'!C3 -> Jun 11, 2026 - 10:50 PM | R24: ='BL Data'!BM3/1000 -> 49 | S24: kW | Y24: Total | Z24: =SUM(C33:AA33) -> 695833.04 | AA24: ='Project Info'!$I$5 -> kBtu
F25: Manual Input | S25: kW | Z25: =IFERROR(Z24/$C$11,0) -> 50.969312 | AA25: =IF('Project Info'!$I$4=Menus!$A$2,"kWh/m²","kBtu/ft²") -> kBtu/ft²
F26: Value Used | G26: =IF(ISBLANK(G25),G24,G25) -> ASHRAE 90.1-2010 Baseline 90° | I26: =IF(ISBLANK(I25),I24,I25) -> Casa De Amparo_v4z 1.pdf | O26: =IF(ISBLANK(O25),O24,O25) -> Jun 11, 2026 - 10:50 PM | R26: =IF(ISBLANK(R25),R24,R25) -> 49 | S26: kW
B28: End Use | C28: Heating | G28: Cooling | I28: Lighting | J28: Exterior Lighting | K28: Equipment | N28: Exterior Equipment | O28: Fans | P28: Pumps | Q28: Heat Rejection | R28: Humidification | S28: Heat Recovery | T28: Water Systems | X28: Refrigeration | Y28: Generators | Z28: ='Project Info'!$I$10 -> 0 | AA28: ='Project Info'!$J$10 -> 0
B29: Fuel Source | C29: Electricity | D29: Gas | E29: Additional Fuel | F29: District Heating | G29: Electricity | H29: District Cooling | I29: Electricity | J29: Electricity | K29: Electricity | L29: Gas | M29: Additional Fuel | N29: Electricity | O29: Electricity | P29: Electricity | Q29: Electricity | R29: Electricity | S29: Electricity | T29: Electricity | U29: Gas | V29: Additional Fuel | W29: District Heating | X29: Electricity | Y29: Electricity | Z29: Electricity | AA29: Electricity
B30: Input Units | C30: ='Project Info'!$I$5 -> kBtu | D30: ='Project Info'!$I$5 -> kBtu | E30: ='Project Info'!$I$5 -> kBtu | F30: ='Project Info'!$I$5 -> kBtu | G30: ='Project Info'!$I$5 -> kBtu | H30: ='Project Info'!$I$5 -> kBtu | I30: ='Project Info'!$I$5 -> kBtu | J30: ='Project Info'!$I$5 -> kBtu | ... AA30: ='Project Info'!$I$5 -> kBtu
B31: Imported Data | C31: ='BL Data'!O3 -> 38006.268 | D31: ='BL Data'!P3 -> 0 | E31: ='BL Data'!Q3 -> 0 | F31: ='BL Data'!R3 -> 0 | G31: ='BL Data'!S3 -> 145037.3 | H31: ='BL Data'!T3 -> 0 | I31: ='BL Data'!U3 -> 153372.81 | J31: ='BL Data'!V3 -> 0 | ... AA31: ='BL Data'!AM3 -> 0
B32: Manual Input
B33: Value Used | C33: =IF(ISBLANK(C32),C31,C32) -> 38006.268 | D33: =IF(ISBLANK(D32),D31,D32) -> 0 | E33: =IF(ISBLANK(E32),E31,E32) -> 0 | F33: =IF(ISBLANK(F32),F31,F32) -> 0 | G33: =IF(ISBLANK(G32),G31,G32) -> 145037.3 | H33: =IF(ISBLANK(H32),H31,H32) -> 0 | I33: =IF(ISBLANK(I32),I31,I32) -> 153372.81 | J33: =IF(ISBLANK(J32),J31,J32) -> 0 | ... AA33: =IF(ISBLANK(AA32),AA31,AA32) -> 0
B35: =IF($C$10=Menus!$I$2,"N/A",_xlfn.CONCAT($A$1," 180° Rotation")) -> LEED Baseline Results Worksheet 180° Rotation
G37: Case Name | I37: Result File Path and Name | O37: Timestamp | R37: Peak Electrical Demand | Y37: Energy Results
F38: Imported Data | G38: ='BL Data'!A4 -> ASHRAE 90.1-2010 Baseline 180° | I38: ='BL Data'!B4 -> Casa De Amparo_v4z 1.pdf | O38: ='BL Data'!C4 -> Jun 11, 2026 - 10:50 PM | R38: ='BL Data'!BM4/1000 -> 49 | S38: kW | Y38: Total | Z38: =SUM(C47:AA47) -> 685835.88 | AA38: ='Project Info'!$I$5 -> kBtu
F39: Manual Input | S39: kW | Z39: =IFERROR(Z38/$C$11,0) -> 50.237026 | AA39: =IF('Project Info'!$I$4=Menus!$A$2,"kWh/m²","kBtu/ft²") -> kBtu/ft²
F40: Value Used | G40: =IF(ISBLANK(G39),G38,G39) -> ASHRAE 90.1-2010 Baseline 180° | I40: =IF(ISBLANK(I39),I38,I39) -> Casa De Amparo_v4z 1.pdf | O40: =IF(ISBLANK(O39),O38,O39) -> Jun 11, 2026 - 10:50 PM | R40: =IF(ISBLANK(R39),R38,R39) -> 49 | S40: kW
B42: End Use | C42: Heating | G42: Cooling | I42: Lighting | J42: Exterior Lighting | K42: Equipment | N42: Exterior Equipment | O42: Fans | P42: Pumps | Q42: Heat Rejection | R42: Humidification | S42: Heat Recovery | T42: Water Systems | X42: Refrigeration | Y42: Generators | Z42: ='Project Info'!$I$10 -> 0 | AA42: ='Project Info'!$J$10 -> 0
B43: Fuel Source | C43: Electricity | D43: Gas | E43: Additional Fuel | F43: District Heating | G43: Electricity | H43: District Cooling | I43: Electricity | J43: Electricity | K43: Electricity | L43: Gas | M43: Additional Fuel | N43: Electricity | O43: Electricity | P43: Electricity | Q43: Electricity | R43: Electricity | S43: Electricity | T43: Electricity | U43: Gas | V43: Additional Fuel | W43: District Heating | X43: Electricity | Y43: Electricity | Z43: Electricity | AA43: Electricity
